log/output_500_2022_GRU_gpu1.log
wandb: Currently logged in as: pqy000 (pqythu). Use `wandb login --relogin` to force relogin
GPU device ID: 1
newdata/500_2022.npy
0
wandb: wandb version 0.17.9 is available!  To upgrade, please run:
wandb:  $ pip install wandb --upgrade
wandb: Tracking run with wandb version 0.12.17
wandb: Run data is saved locally in /home/qingyi/GPU20/DeepLOB/wandb/run-20240907_120926-1yifeczt
wandb: Run `wandb offline` to turn off syncing.
wandb: Syncing run GRU
wandb: ⭐️ View project at https://wandb.ai/pqythu/futures500
wandb: 🚀 View run at https://wandb.ai/pqythu/futures500/runs/1yifeczt
2024-09-07 12:09:34.846971: I tensorflow/core/platform/cpu_feature_guard.cc:193] This TensorFlow binary is optimized with oneAPI Deep Neural Network Library (oneDNN) to use the following CPU instructions in performance-critical operations:  AVX2 FMA
To enable them in other operations, rebuild TensorFlow with the appropriate compiler flags.
2024-09-07 12:09:36.114525: W tensorflow/compiler/xla/stream_executor/platform/default/dso_loader.cc:64] Could not load dynamic library 'libnvinfer.so.7'; dlerror: libnvinfer.so.7: cannot open shared object file: No such file or directory; LD_LIBRARY_PATH: /opt/cudnn/lib64:/usr/local/cuda/lib64
2024-09-07 12:09:36.114633: W tensorflow/compiler/xla/stream_executor/platform/default/dso_loader.cc:64] Could not load dynamic library 'libnvinfer_plugin.so.7'; dlerror: libnvinfer_plugin.so.7: cannot open shared object file: No such file or directory; LD_LIBRARY_PATH: /opt/cudnn/lib64:/usr/local/cuda/lib64
2024-09-07 12:09:36.114646: W tensorflow/compiler/tf2tensorrt/utils/py_utils.cc:38] TF-TRT Warning: Cannot dlopen some TensorRT libraries. If you would like to use Nvidia GPU with TensorRT, please make sure the missing libraries mentioned above are installed properly.
Model(
  (rnn): GRU(10, 64, batch_first=True)
  (fc): Linear(in_features=64, out_features=5, bias=True)
)
number of parameters: 14917
Training start
epoch  1 | time used:  1.04s | train_loss 1.573 | valid loss 1.642 | valid acc 0.190 | mae 2.065 | mse 6.215 | rmse 2.49 | r2 -2.19 | sharp 0.00
epoch  2 | time used:  0.11s | train_loss 1.568 | valid loss 1.526 | valid acc 0.235 | mae 1.935 | mse 5.695 | rmse 2.39 | r2 -1.92 | sharp 0.82
epoch  3 | time used:  0.10s | train_loss 1.559 | valid loss 1.526 | valid acc 0.235 | mae 1.935 | mse 5.695 | rmse 2.39 | r2 -1.92 | sharp 0.82
epoch  4 | time used:  0.08s | train_loss 1.560 | valid loss 1.526 | valid acc 0.235 | mae 1.935 | mse 5.695 | rmse 2.39 | r2 -1.92 | sharp 0.82
epoch  5 | time used:  0.10s | train_loss 1.561 | valid loss 1.526 | valid acc 0.235 | mae 1.935 | mse 5.695 | rmse 2.39 | r2 -1.92 | sharp 0.82
epoch  6 | time used:  0.10s | train_loss 1.596 | valid loss 1.642 | valid acc 0.190 | mae 2.065 | mse 6.215 | rmse 2.49 | r2 -2.19 | sharp 0.00
epoch  7 | time used:  0.09s | train_loss 1.565 | valid loss 1.642 | valid acc 0.190 | mae 2.065 | mse 6.215 | rmse 2.49 | r2 -2.19 | sharp 0.00
epoch  8 | time used:  0.10s | train_loss 1.563 | valid loss 1.642 | valid acc 0.190 | mae 2.065 | mse 6.215 | rmse 2.49 | r2 -2.19 | sharp 0.00
epoch  9 | time used:  0.10s | train_loss 1.570 | valid loss 1.642 | valid acc 0.190 | mae 2.065 | mse 6.215 | rmse 2.49 | r2 -2.19 | sharp 0.00
epoch 10 | time used:  0.09s | train_loss 1.565 | valid loss 1.642 | valid acc 0.190 | mae 2.065 | mse 6.215 | rmse 2.49 | r2 -2.19 | sharp 0.00
saving the model to ./save/2022_500/GRU/checkpoint10.pt
epoch 11 | time used:  0.10s | train_loss 1.556 | valid loss 1.642 | valid acc 0.190 | mae 2.065 | mse 6.215 | rmse 2.49 | r2 -2.19 | sharp 0.00
epoch 12 | time used:  0.10s | train_loss 1.590 | valid loss 1.526 | valid acc 0.235 | mae 1.935 | mse 5.695 | rmse 2.39 | r2 -1.92 | sharp 0.82
epoch 13 | time used:  0.10s | train_loss 1.552 | valid loss 1.526 | valid acc 0.235 | mae 1.935 | mse 5.695 | rmse 2.39 | r2 -1.92 | sharp 0.82
epoch 14 | time used:  0.11s | train_loss 1.571 | valid loss 1.642 | valid acc 0.190 | mae 2.065 | mse 6.215 | rmse 2.49 | r2 -2.19 | sharp 0.00
epoch 15 | time used:  0.12s | train_loss 1.564 | valid loss 1.642 | valid acc 0.190 | mae 2.065 | mse 6.215 | rmse 2.49 | r2 -2.19 | sharp 0.00
epoch 16 | time used:  0.09s | train_loss 1.559 | valid loss 1.642 | valid acc 0.190 | mae 2.065 | mse 6.215 | rmse 2.49 | r2 -2.19 | sharp 0.00
epoch 17 | time used:  0.11s | train_loss 1.557 | valid loss 1.526 | valid acc 0.235 | mae 1.935 | mse 5.695 | rmse 2.39 | r2 -1.92 | sharp 0.82
epoch 18 | time used:  0.13s | train_loss 1.556 | valid loss 1.526 | valid acc 0.235 | mae 1.935 | mse 5.695 | rmse 2.39 | r2 -1.92 | sharp 0.82
epoch 19 | time used:  0.09s | train_loss 1.557 | valid loss 1.526 | valid acc 0.235 | mae 1.935 | mse 5.695 | rmse 2.39 | r2 -1.92 | sharp 0.82
epoch 20 | time used:  0.07s | train_loss 1.550 | valid loss 1.526 | valid acc 0.235 | mae 1.935 | mse 5.695 | rmse 2.39 | r2 -1.92 | sharp 0.82
saving the model to ./save/2022_500/GRU/checkpoint20.pt
epoch 21 | time used:  0.08s | train_loss 1.574 | valid loss 1.726 | valid acc 0.320 | mae 1.105 | mse 1.955 | rmse 1.40 | r2 -0.00 | sharp 0.82
epoch 22 | time used:  0.09s | train_loss 1.572 | valid loss 1.526 | valid acc 0.235 | mae 1.935 | mse 5.695 | rmse 2.39 | r2 -1.92 | sharp 0.82
epoch 23 | time used:  0.11s | train_loss 1.570 | valid loss 1.642 | valid acc 0.190 | mae 2.065 | mse 6.215 | rmse 2.49 | r2 -2.19 | sharp 0.00
epoch 24 | time used:  0.14s | train_loss 1.567 | valid loss 1.642 | valid acc 0.190 | mae 2.065 | mse 6.215 | rmse 2.49 | r2 -2.19 | sharp 0.00
epoch 25 | time used:  0.16s | train_loss 1.561 | valid loss 1.526 | valid acc 0.235 | mae 1.935 | mse 5.695 | rmse 2.39 | r2 -1.92 | sharp 0.82
epoch 26 | time used:  0.10s | train_loss 1.553 | valid loss 1.526 | valid acc 0.235 | mae 1.935 | mse 5.695 | rmse 2.39 | r2 -1.92 | sharp 0.82
epoch 27 | time used:  0.09s | train_loss 1.560 | valid loss 1.526 | valid acc 0.235 | mae 1.935 | mse 5.695 | rmse 2.39 | r2 -1.92 | sharp 0.82
epoch 28 | time used:  0.13s | train_loss 1.554 | valid loss 1.526 | valid acc 0.235 | mae 1.935 | mse 5.695 | rmse 2.39 | r2 -1.92 | sharp 0.82
epoch 29 | time used:  0.10s | train_loss 1.552 | valid loss 1.526 | valid acc 0.235 | mae 1.935 | mse 5.695 | rmse 2.39 | r2 -1.92 | sharp 0.82
epoch 30 | time used:  0.12s | train_loss 1.555 | valid loss 1.552 | valid acc 0.235 | mae 1.935 | mse 5.695 | rmse 2.39 | r2 -1.92 | sharp 0.82
saving the model to ./save/2022_500/GRU/checkpoint30.pt
epoch 31 | time used:  0.08s | train_loss 1.553 | valid loss 1.526 | valid acc 0.235 | mae 1.935 | mse 5.695 | rmse 2.39 | r2 -1.92 | sharp 0.82
epoch 32 | time used:  0.08s | train_loss 1.553 | valid loss 1.525 | valid acc 0.235 | mae 1.935 | mse 5.695 | rmse 2.39 | r2 -1.92 | sharp 0.82
epoch 33 | time used:  0.08s | train_loss 1.562 | valid loss 1.526 | valid acc 0.235 | mae 1.935 | mse 5.695 | rmse 2.39 | r2 -1.92 | sharp 0.82
epoch 34 | time used:  0.09s | train_loss 1.549 | valid loss 1.642 | valid acc 0.190 | mae 2.065 | mse 6.215 | rmse 2.49 | r2 -2.19 | sharp 0.00
epoch 35 | time used:  0.08s | train_loss 1.566 | valid loss 1.642 | valid acc 0.190 | mae 2.065 | mse 6.215 | rmse 2.49 | r2 -2.19 | sharp 0.00
epoch 36 | time used:  0.07s | train_loss 1.562 | valid loss 1.642 | valid acc 0.190 | mae 2.065 | mse 6.215 | rmse 2.49 | r2 -2.19 | sharp 0.00
epoch 37 | time used:  0.07s | train_loss 1.547 | valid loss 1.526 | valid acc 0.235 | mae 1.935 | mse 5.695 | rmse 2.39 | r2 -1.92 | sharp 0.82
epoch 38 | time used:  0.07s | train_loss 1.556 | valid loss 1.526 | valid acc 0.235 | mae 1.935 | mse 5.695 | rmse 2.39 | r2 -1.92 | sharp 0.82
epoch 39 | time used:  0.07s | train_loss 1.576 | valid loss 1.526 | valid acc 0.235 | mae 1.935 | mse 5.695 | rmse 2.39 | r2 -1.92 | sharp 0.82
epoch 40 | time used:  0.07s | train_loss 1.572 | valid loss 1.610 | valid acc 0.115 | mae 1.405 | mse 2.825 | rmse 1.68 | r2 -0.45 | sharp 0.82
saving the model to ./save/2022_500/GRU/checkpoint40.pt
