log/output_500_2022_GRU_gpu2.log
wandb: Currently logged in as: pqy000 (pqythu). Use `wandb login --relogin` to force relogin
GPU device ID: 2
newdata/500_2022.npy
0
2024-09-07 11:35:16.186578: I tensorflow/core/platform/cpu_feature_guard.cc:193] This TensorFlow binary is optimized with oneAPI Deep Neural Network Library (oneDNN) to use the following CPU instructions in performance-critical operations:  AVX2 FMA
To enable them in other operations, rebuild TensorFlow with the appropriate compiler flags.
2024-09-07 11:35:17.128058: W tensorflow/compiler/xla/stream_executor/platform/default/dso_loader.cc:64] Could not load dynamic library 'libnvinfer.so.7'; dlerror: libnvinfer.so.7: cannot open shared object file: No such file or directory; LD_LIBRARY_PATH: /opt/cudnn/lib64:/usr/local/cuda/lib64
2024-09-07 11:35:17.128162: W tensorflow/compiler/xla/stream_executor/platform/default/dso_loader.cc:64] Could not load dynamic library 'libnvinfer_plugin.so.7'; dlerror: libnvinfer_plugin.so.7: cannot open shared object file: No such file or directory; LD_LIBRARY_PATH: /opt/cudnn/lib64:/usr/local/cuda/lib64
2024-09-07 11:35:17.128175: W tensorflow/compiler/tf2tensorrt/utils/py_utils.cc:38] TF-TRT Warning: Cannot dlopen some TensorRT libraries. If you would like to use Nvidia GPU with TensorRT, please make sure the missing libraries mentioned above are installed properly.
wandb: wandb version 0.17.9 is available!  To upgrade, please run:
wandb:  $ pip install wandb --upgrade
wandb: Tracking run with wandb version 0.12.17
wandb: Run data is saved locally in /home/qingyi/GPU20/DeepLOB/wandb/run-20240907_113513-27ofg9pq
wandb: Run `wandb offline` to turn off syncing.
wandb: Syncing run GRU
wandb: ⭐️ View project at https://wandb.ai/pqythu/futures500
wandb: 🚀 View run at https://wandb.ai/pqythu/futures500/runs/27ofg9pq
Model(
  (rnn): GRU(10, 64, batch_first=True)
  (fc): Linear(in_features=64, out_features=5, bias=True)
)
number of parameters: 14917
Training start
epoch  1 | time used:  1.00s | train_loss 1.544 | valid loss 1.537 | valid acc 0.292 | mae 2.159 | mse 7.486 | rmse 2.74 | r2 -1.65 | sharp 2.43
epoch  2 | time used:  0.21s | train_loss 1.457 | valid loss 1.537 | valid acc 0.292 | mae 2.159 | mse 7.486 | rmse 2.74 | r2 -1.65 | sharp 2.43
epoch  3 | time used:  0.22s | train_loss 1.510 | valid loss 1.464 | valid acc 0.376 | mae 1.841 | mse 6.216 | rmse 2.49 | r2 -1.20 | sharp 0.00
epoch  4 | time used:  0.17s | train_loss 1.464 | valid loss 1.537 | valid acc 0.292 | mae 2.159 | mse 7.486 | rmse 2.74 | r2 -1.65 | sharp 2.43
epoch  5 | time used:  0.12s | train_loss 1.456 | valid loss 1.537 | valid acc 0.292 | mae 2.159 | mse 7.486 | rmse 2.74 | r2 -1.65 | sharp 2.43
epoch  6 | time used:  0.13s | train_loss 1.467 | valid loss 1.537 | valid acc 0.292 | mae 2.159 | mse 7.486 | rmse 2.74 | r2 -1.65 | sharp 2.43
epoch  7 | time used:  0.16s | train_loss 1.459 | valid loss 1.466 | valid acc 0.376 | mae 1.841 | mse 6.216 | rmse 2.49 | r2 -1.20 | sharp 0.00
epoch  8 | time used:  0.21s | train_loss 1.557 | valid loss 1.464 | valid acc 0.376 | mae 1.841 | mse 6.216 | rmse 2.49 | r2 -1.20 | sharp 0.00
epoch  9 | time used:  0.17s | train_loss 1.536 | valid loss 1.537 | valid acc 0.292 | mae 2.159 | mse 7.486 | rmse 2.74 | r2 -1.65 | sharp 2.43
epoch 10 | time used:  0.16s | train_loss 1.466 | valid loss 1.537 | valid acc 0.292 | mae 2.159 | mse 7.486 | rmse 2.74 | r2 -1.65 | sharp 2.43
saving the model to ./save/2022_500/GRU/checkpoint10.pt
epoch 11 | time used:  0.17s | train_loss 1.458 | valid loss 1.537 | valid acc 0.292 | mae 2.159 | mse 7.486 | rmse 2.74 | r2 -1.65 | sharp 2.43
epoch 12 | time used:  0.20s | train_loss 1.453 | valid loss 1.537 | valid acc 0.292 | mae 2.159 | mse 7.486 | rmse 2.74 | r2 -1.65 | sharp 2.43
epoch 13 | time used:  0.18s | train_loss 1.470 | valid loss 1.464 | valid acc 0.376 | mae 1.841 | mse 6.216 | rmse 2.49 | r2 -1.20 | sharp 0.00
epoch 14 | time used:  0.25s | train_loss 1.558 | valid loss 1.465 | valid acc 0.376 | mae 1.841 | mse 6.216 | rmse 2.49 | r2 -1.20 | sharp 0.00
epoch 15 | time used:  0.21s | train_loss 1.498 | valid loss 1.537 | valid acc 0.292 | mae 2.159 | mse 7.486 | rmse 2.74 | r2 -1.65 | sharp 2.43
epoch 16 | time used:  0.25s | train_loss 1.459 | valid loss 1.511 | valid acc 0.292 | mae 2.159 | mse 7.486 | rmse 2.74 | r2 -1.65 | sharp 2.43
epoch 17 | time used:  0.16s | train_loss 1.457 | valid loss 1.537 | valid acc 0.292 | mae 2.159 | mse 7.486 | rmse 2.74 | r2 -1.65 | sharp 2.43
epoch 18 | time used:  0.14s | train_loss 1.481 | valid loss 1.464 | valid acc 0.376 | mae 1.841 | mse 6.216 | rmse 2.49 | r2 -1.20 | sharp 0.00
epoch 19 | time used:  0.20s | train_loss 1.505 | valid loss 1.537 | valid acc 0.292 | mae 2.159 | mse 7.486 | rmse 2.74 | r2 -1.65 | sharp 2.43
epoch 20 | time used:  0.20s | train_loss 1.531 | valid loss 1.464 | valid acc 0.376 | mae 1.841 | mse 6.216 | rmse 2.49 | r2 -1.20 | sharp 0.00
saving the model to ./save/2022_500/GRU/checkpoint20.pt
epoch 21 | time used:  0.19s | train_loss 1.528 | valid loss 1.537 | valid acc 0.292 | mae 2.159 | mse 7.486 | rmse 2.74 | r2 -1.65 | sharp 2.43
epoch 22 | time used:  0.18s | train_loss 1.461 | valid loss 1.537 | valid acc 0.292 | mae 2.159 | mse 7.486 | rmse 2.74 | r2 -1.65 | sharp 2.43
epoch 23 | time used:  0.14s | train_loss 1.472 | valid loss 1.537 | valid acc 0.292 | mae 2.159 | mse 7.486 | rmse 2.74 | r2 -1.65 | sharp 2.43
epoch 24 | time used:  0.15s | train_loss 1.457 | valid loss 1.537 | valid acc 0.292 | mae 2.159 | mse 7.486 | rmse 2.74 | r2 -1.65 | sharp 2.43
epoch 25 | time used:  0.14s | train_loss 1.465 | valid loss 1.537 | valid acc 0.292 | mae 2.159 | mse 7.486 | rmse 2.74 | r2 -1.65 | sharp 2.43
epoch 26 | time used:  0.18s | train_loss 1.508 | valid loss 1.537 | valid acc 0.292 | mae 2.159 | mse 7.486 | rmse 2.74 | r2 -1.65 | sharp 2.43
epoch 27 | time used:  0.19s | train_loss 1.463 | valid loss 1.537 | valid acc 0.292 | mae 2.159 | mse 7.486 | rmse 2.74 | r2 -1.65 | sharp 2.43
epoch 28 | time used:  0.19s | train_loss 1.476 | valid loss 1.464 | valid acc 0.376 | mae 1.841 | mse 6.216 | rmse 2.49 | r2 -1.20 | sharp 0.00
epoch 29 | time used:  0.17s | train_loss 1.530 | valid loss 1.537 | valid acc 0.292 | mae 2.159 | mse 7.486 | rmse 2.74 | r2 -1.65 | sharp 2.43
epoch 30 | time used:  0.18s | train_loss 1.459 | valid loss 1.537 | valid acc 0.292 | mae 2.159 | mse 7.486 | rmse 2.74 | r2 -1.65 | sharp 2.43
saving the model to ./save/2022_500/GRU/checkpoint30.pt
epoch 31 | time used:  0.16s | train_loss 1.492 | valid loss 1.464 | valid acc 0.376 | mae 1.841 | mse 6.216 | rmse 2.49 | r2 -1.20 | sharp 0.00
epoch 32 | time used:  0.16s | train_loss 1.489 | valid loss 1.537 | valid acc 0.292 | mae 2.159 | mse 7.486 | rmse 2.74 | r2 -1.65 | sharp 2.43
epoch 33 | time used:  0.18s | train_loss 1.622 | valid loss 1.537 | valid acc 0.292 | mae 2.159 | mse 7.486 | rmse 2.74 | r2 -1.65 | sharp 2.43
epoch 34 | time used:  0.21s | train_loss 1.454 | valid loss 1.537 | valid acc 0.292 | mae 2.159 | mse 7.486 | rmse 2.74 | r2 -1.65 | sharp 2.43
epoch 35 | time used:  0.20s | train_loss 1.580 | valid loss 1.825 | valid acc 0.092 | mae 1.744 | mse 4.169 | rmse 2.04 | r2 -0.48 | sharp 2.43
epoch 36 | time used:  0.18s | train_loss 1.679 | valid loss 1.825 | valid acc 0.092 | mae 1.744 | mse 4.169 | rmse 2.04 | r2 -0.48 | sharp 2.43
epoch 37 | time used:  0.18s | train_loss 1.502 | valid loss 1.537 | valid acc 0.292 | mae 2.159 | mse 7.486 | rmse 2.74 | r2 -1.65 | sharp 2.43
epoch 38 | time used:  0.17s | train_loss 1.459 | valid loss 1.537 | valid acc 0.292 | mae 2.159 | mse 7.486 | rmse 2.74 | r2 -1.65 | sharp 2.43
epoch 39 | time used:  0.18s | train_loss 1.464 | valid loss 1.537 | valid acc 0.292 | mae 2.159 | mse 7.486 | rmse 2.74 | r2 -1.65 | sharp 2.43
epoch 40 | time used:  0.20s | train_loss 1.480 | valid loss 1.464 | valid acc 0.376 | mae 1.841 | mse 6.216 | rmse 2.49 | r2 -1.20 | sharp 0.00
saving the model to ./save/2022_500/GRU/checkpoint40.pt
